<sdf version='1.7'>
  <model name='rs_robot'>
    <link name='base_link'>
      <inertial>
        <pose>-0.021738 0.001259 0.059907 0 -0 0</pose>
        <mass>13.3401</mass>
        <inertia>
          <ixx>1.20957</ixx>
          <ixy>-0.0024652</ixy>
          <ixz>0.00863852</ixz>
          <iyy>1.32216</iyy>
          <iyz>-0.00379622</iyz>
          <izz>1.23979</izz>
        </inertia>
      </inertial>
      <collision name='base_link_fixed_joint_lump__chassis_collision'>
        <pose>-0.045 0 0.148 0 -0 0</pose>
        <geometry>
          <box>
            <size>0.225 0.22 0.108</size>
          </box>
        </geometry>
        <surface>
          <contact>
            <ode/>
          </contact>
          <friction>
            <ode/>
          </friction>
        </surface>
      </collision>
      <collision name='base_link_fixed_joint_lump__cameraD_collision_1'>
        <pose>0.025 0 0.32 0 1.5708 0</pose>
        <geometry>
          <cylinder>
            <length>0.1</length>
            <radius>0.03</radius>
          </cylinder>
        </geometry>
        <surface>
          <contact>
            <ode/>
          </contact>
          <friction>
            <ode/>
          </friction>
        </surface>
      </collision>
      <collision name='base_link_fixed_joint_lump__front_camera_collision_2'>
        <pose>0.025 0 0.32 0 1.5708 0</pose>
        <geometry>
          <cylinder>
            <length>0.1</length>
            <radius>0.03</radius>
          </cylinder>
        </geometry>
        <surface>
          <contact>
            <ode/>
          </contact>
          <friction>
            <ode/>
          </friction>
        </surface>
      </collision>
      <collision name='base_link_fixed_joint_lump__front_laser_collision_3'>
        <pose>0.125 0 0.25 0 -0 0</pose>
        <geometry>
          <box>
            <size>0.1 0.1 0.1</size>
          </box>
        </geometry>
      </collision>
      <collision name='base_link_fixed_joint_lump__sonar_collision_4'>
        <pose>0.109 0 0.209 0 -0 0</pose>
        <geometry>
          <box>
            <size>0.01 0.01 0.01</size>
          </box>
        </geometry>
        <surface>
          <contact>
            <ode/>
          </contact>
          <friction>
            <ode/>
          </friction>
        </surface>
      </collision>
      <collision name='base_link_fixed_joint_lump__top_collision_5'>
        <pose>-0.045 0 0.234 0 -0 0</pose>
        <geometry>
          <mesh>
            <scale>1 1 1</scale>
            <uri>model://td3/urdf/meshes/p3dx/top.stl</uri>
          </mesh>
        </geometry>
        <surface>
          <contact>
            <ode/>
          </contact>
          <friction>
            <ode/>
          </friction>
        </surface>
      </collision>
      <collision name='base_link_fixed_joint_lump__velodyne_base_link_collision_6'>
        <pose>0.125 0.02 0.28585 0 -0 0</pose>
        <geometry>
          <cylinder>
            <length>0.0717</length>
            <radius>0.0516</radius>
          </cylinder>
        </geometry>
      </collision>
      <visual name='base_link_fixed_joint_lump__chassis_visual_visual'>
        <pose>-0.045 0 0.148 0 -0 0</pose>
        <geometry>
          <box>
            <size>0.225 0.22 0.108</size>
          </box>
        </geometry>
        <material>
          <script>
            <name>Gazebo/Green</name>
            <uri>file://media/materials/scripts/gazebo.material</uri>
          </script>
        </material>
      </visual>
      <visual name='base_link_fixed_joint_lump__battery0_visual_visual_1'>
        <pose>-0.14 0 0.13 0 -0 0</pose>
        <geometry>
          <box>
            <size>0.151 0.065 0.094</size>
          </box>
        </geometry>
        <material>
          <script>
            <name>Gazebo/Black</name>
            <uri>file://media/materials/scripts/gazebo.material</uri>
          </script>
        </material>
      </visual>
      <visual name='base_link_fixed_joint_lump__cameraD_visual_2'>
        <pose>0.025 0 0.32 0 1.5708 0</pose>
        <geometry>
          <cylinder>
            <length>0.1</length>
            <radius>0.03</radius>
          </cylinder>
        </geometry>
        <material>
          <script>
            <name>Gazebo/Grey</name>
            <uri>file://media/materials/scripts/gazebo.material</uri>
          </script>
        </material>
      </visual>
      <visual name='base_link_fixed_joint_lump__front_camera_visual_3'>
        <pose>0.025 0 0.32 0 1.5708 0</pose>
        <geometry>
          <cylinder>
            <length>0.1</length>
            <radius>0.03</radius>
          </cylinder>
        </geometry>
        <material>
          <script>
            <name>Gazebo/Grey</name>
            <uri>file://media/materials/scripts/gazebo.material</uri>
          </script>
        </material>
      </visual>
      <visual name='base_link_fixed_joint_lump__front_laser_visual_4'>
        <pose>0.125 0 0.25 0 -0 0</pose>
        <geometry>
          <mesh>
            <scale>1 1 1</scale>
            <uri>model://td3/urdf/meshes/laser/hokuyo.dae</uri>
          </mesh>
        </geometry>
      </visual>
      <visual name='base_link_fixed_joint_lump__front_sonar_vis_visual_5'>
        <pose>0.109 0 0.209 0 -0 0</pose>
        <geometry>
          <mesh>
            <scale>1 1 1</scale>
            <uri>model://td3/urdf/meshes/p3dx/back_sonar.stl</uri>
          </mesh>
        </geometry>
      </visual>
      <visual name='base_link_fixed_joint_lump__top_visual_6'>
        <pose>-0.045 0 0.234 0 -0 0</pose>
        <geometry>
          <mesh>
            <scale>1 1 1</scale>
            <uri>model://td3/urdf/meshes/p3dx/top.stl</uri>
          </mesh>
        </geometry>
        <material>
          <script>
            <name>Gazebo/Black</name>
            <uri>file://media/materials/scripts/gazebo.material</uri>
          </script>
        </material>
      </visual>
      <visual name='base_link_fixed_joint_lump__velodyne_base_link_visual_7'>
        <pose>0.125 0.02 0.25 0 -0 0</pose>
        <geometry>
          <mesh>
            <scale>1 1 1</scale>
            <uri>model://velodyne_description/meshes/VLP16_base_1.dae</uri>
          </mesh>
        </geometry>
      </visual>
      <visual name='base_link_fixed_joint_lump__velodyne_base_link_visual_8'>
        <pose>0.125 0.02 0.25 0 -0 0</pose>
        <geometry>
          <mesh>
            <scale>1 1 1</scale>
            <uri>model://velodyne_description/meshes/VLP16_base_2.dae</uri>
          </mesh>
        </geometry>
      </visual>
      <visual name='base_link_fixed_joint_lump__velodyne_visual_9'>
        <pose>0.125 0.02 0.25 0 -0 0</pose>
        <geometry>
          <mesh>
            <scale>1 1 1</scale>
            <uri>model://velodyne_description/meshes/VLP16_scan.dae</uri>
          </mesh>
        </geometry>
      </visual>
    </link>
    <joint name='chassis_swivel_joint' type='revolute'>
      <pose relative_to='base_link'>-0.185 0 0.055 0 -0 0</pose>
      <parent>base_link</parent>
      <child>swivel</child>
      <axis>
        <xyz>0 0 1</xyz>
        <limit>
          <effort>100</effort>
          <velocity>100</velocity>
          <lower>-1e+16</lower>
          <upper>1e+16</upper>
        </limit>
        <dynamics>
          <spring_reference>0</spring_reference>
          <spring_stiffness>0</spring_stiffness>
        </dynamics>
      </axis>
    </joint>
    <link name='swivel'>
      <pose relative_to='chassis_swivel_joint'>0 0 0 0 -0 0</pose>
      <inertial>
        <pose>0 0 0 0 -0 0</pose>
        <mass>0.1</mass>
        <inertia>
          <ixx>0.01</ixx>
          <ixy>0</ixy>
          <ixz>0</ixz>
          <iyy>0.01</iyy>
          <iyz>0</iyz>
          <izz>0.01</izz>
        </inertia>
      </inertial>
      <collision name='swivel_collision'>
        <pose>0 0 0 0 -0 0</pose>
        <geometry>
          <box>
            <size>0.01 0.01 0.01</size>
          </box>
        </geometry>
        <surface>
          <contact>
            <ode/>
          </contact>
          <friction>
            <ode/>
          </friction>
        </surface>
      </collision>
      <visual name='swivel_fixed_joint_lump__base_visual_visual'>
        <pose>0 0 0 0 -0 0</pose>
        <geometry>
          <mesh>
            <scale>1 1 1</scale>
            <uri>model://td3/urdf/meshes/p3dx/swivel.stl</uri>
          </mesh>
        </geometry>
      </visual>
    </link>
    <joint name='swivel_wheel_joint' type='revolute'>
      <pose relative_to='swivel'>-0.026 0 -0.016 0 -0 0</pose>
      <parent>swivel</parent>
      <child>center_wheel</child>
      <axis>
        <xyz>0 1 0</xyz>
        <limit>
          <effort>100</effort>
          <velocity>100</velocity>
          <lower>-1e+16</lower>
          <upper>1e+16</upper>
        </limit>
        <dynamics>
          <spring_reference>0</spring_reference>
          <spring_stiffness>0</spring_stiffness>
        </dynamics>
      </axis>
    </joint>
    <link name='center_wheel'>
      <pose relative_to='swivel_wheel_joint'>0 0 0 0 -0 0</pose>
      <inertial>
        <pose>-0.000318 0 -9.1e-05 0 -0 0</pose>
        <mass>0.11</mass>
        <inertia>
          <ixx>0.0248235</ixx>
          <ixy>-0.00142347</ixy>
          <ixz>0.00100543</ixz>
          <iyy>0.0304364</iyy>
          <iyz>-8.54693e-06</iyz>
          <izz>0.0235281</izz>
        </inertia>
      </inertial>
      <collision name='center_wheel_collision'>
        <pose>0 0 0 -1.5708 0 0</pose>
        <geometry>
          <cylinder>
            <length>0.01</length>
            <radius>0.0375</radius>
          </cylinder>
        </geometry>
        <surface>
          <contact>
            <ode/>
          </contact>
          <friction>
            <ode/>
          </friction>
        </surface>
      </collision>
      <collision name='center_wheel_fixed_joint_lump__center_hubcap_collision_1'>
        <pose>-0.0035 0 -0.001 0 -0 0</pose>
        <geometry>
          <box>
            <size>0.01 0.01 0.01</size>
          </box>
        </geometry>
        <surface>
          <contact>
            <ode/>
          </contact>
          <friction>
            <ode/>
          </friction>
        </surface>
      </collision>
      <visual name='center_wheel_fixed_joint_lump__base_visual_visual'>
        <pose>0 0 0 0 -0 0</pose>
        <geometry>
          <mesh>
            <scale>1 1 1</scale>
            <uri>model://td3/urdf/meshes/p3dx/center_wheel.stl</uri>
          </mesh>
        </geometry>
      </visual>
      <visual name='center_wheel_fixed_joint_lump__base_visual_visual_1'>
        <pose>-0.0035 0 -0.001 0 -0 0</pose>
        <geometry>
          <mesh>
            <scale>1 1 1</scale>
            <uri>model://td3/urdf/meshes/p3dx/center_hubcap.stl</uri>
          </mesh>
        </geometry>
      </visual>
    </link>
    <joint name='left_hub_joint' type='revolute'>
      <pose relative_to='base_link'>0 -0.15 0.09 0 -0 0</pose>
      <parent>base_link</parent>
      <child>left_hub</child>
      <axis>
        <xyz>0 1 0</xyz>
        <limit>
          <lower>-1e+16</lower>
          <upper>1e+16</upper>
        </limit>
        <dynamics>
          <spring_reference>0</spring_reference>
          <spring_stiffness>0</spring_stiffness>
        </dynamics>
      </axis>
    </joint>
    <link name='left_hub'>
      <pose relative_to='left_hub_joint'>0 0 0 0 -0 0</pose>
      <inertial>
        <pose>0 0 0 0 -0 0</pose>
        <mass>0.51</mass>
        <inertia>
          <ixx>0.0248235</ixx>
          <ixy>0</ixy>
          <ixz>0</ixz>
          <iyy>0.0304363</iyy>
          <iyz>0</iyz>
          <izz>0.023528</izz>
        </inertia>
      </inertial>
      <collision name='left_hub_collision'>
        <pose>0 0 0 0 -0 0</pose>
        <geometry>
          <box>
            <size>0.01 0.01 0.01</size>
          </box>
        </geometry>
        <surface>
          <contact>
            <ode/>
          </contact>
          <friction>
            <ode/>
          </friction>
        </surface>
      </collision>
      <collision name='left_hub_fixed_joint_lump__left_wheel_collision_1'>
        <pose>0 0 0 -1.5708 0 0</pose>
        <geometry>
          <cylinder>
            <length>0.01</length>
            <radius>0.09</radius>
          </cylinder>
        </geometry>
        <surface>
          <contact>
            <ode/>
          </contact>
          <friction>
            <ode/>
          </friction>
        </surface>
      </collision>
      <visual name='left_hub_fixed_joint_lump__base_visual_visual'>
        <pose>0 0 0 0 -0 0</pose>
        <geometry>
          <mesh>
            <scale>1 1 1</scale>
            <uri>model://td3/urdf/meshes/p3dx/left_hubcap.stl</uri>
          </mesh>
        </geometry>
      </visual>
      <visual name='left_hub_fixed_joint_lump__base_visual_visual_1'>
        <pose>0 0 0 0 -0 0</pose>
        <geometry>
          <mesh>
            <scale>1 1 1</scale>
            <uri>model://td3/urdf/meshes/p3dx/left_wheel.stl</uri>
          </mesh>
        </geometry>
      </visual>
    </link>
    <joint name='right_hub_joint' type='revolute'>
      <pose relative_to='base_link'>0 0.15 0.09 0 -0 0</pose>
      <parent>base_link</parent>
      <child>right_hub</child>
      <axis>
        <xyz>0 1 0</xyz>
        <limit>
          <lower>-1e+16</lower>
          <upper>1e+16</upper>
        </limit>
        <dynamics>
          <spring_reference>0</spring_reference>
          <spring_stiffness>0</spring_stiffness>
        </dynamics>
      </axis>
    </joint>
    <link name='right_hub'>
      <pose relative_to='right_hub_joint'>0 0 0 0 -0 0</pose>
      <inertial>
        <pose>0 0 0 0 -0 0</pose>
        <mass>0.51</mass>
        <inertia>
          <ixx>0.0248235</ixx>
          <ixy>0</ixy>
          <ixz>0</ixz>
          <iyy>0.0304363</iyy>
          <iyz>0</iyz>
          <izz>0.023528</izz>
        </inertia>
      </inertial>
      <collision name='right_hub_collision'>
        <pose>0 0 0 0 -0 0</pose>
        <geometry>
          <box>
            <size>0.01 0.01 0.01</size>
          </box>
        </geometry>
        <surface>
          <contact>
            <ode/>
          </contact>
          <friction>
            <ode/>
          </friction>
        </surface>
      </collision>
      <collision name='right_hub_fixed_joint_lump__right_wheel_collision_1'>
        <pose>0 0 0 -1.5708 0 0</pose>
        <geometry>
          <cylinder>
            <length>0.01</length>
            <radius>0.09</radius>
          </cylinder>
        </geometry>
        <surface>
          <contact>
            <ode/>
          </contact>
          <friction>
            <ode/>
          </friction>
        </surface>
      </collision>
      <visual name='right_hub_fixed_joint_lump__base_visual_visual'>
        <pose>0 0 0 0 -0 0</pose>
        <geometry>
          <mesh>
            <scale>1 1 1</scale>
            <uri>model://td3/urdf/meshes/p3dx/right_hubcap.stl</uri>
          </mesh>
        </geometry>
      </visual>
      <visual name='right_hub_fixed_joint_lump__base_visual_visual_1'>
        <pose>0 0 0 0 -0 0</pose>
        <geometry>
          <mesh>
            <scale>1 1 1</scale>
            <uri>model://td3/urdf/meshes/p3dx/right_wheel.stl</uri>
          </mesh>
        </geometry>
      </visual>
    </link>
  </model>
</sdf>
